INFO:root:ðŸ”§ Checking and fixing migration state...
INFO:root:ðŸ”§ Found existing user_email_config table, ensuring migration state is correct
INFO:root:âœ… RAILWAY DATABASE INITIALIZATION COMPLETE
INFO  [alembic.runtime.migration] Context impl PostgresqlImpl.
INFO  [alembic.runtime.migration] Will assume transactional DDL.
INFO  [alembic.runtime.migration] Running upgrade 20250929_2303 -> 20251003_0100, add image metadata fields (hash, content_type, size) to fotos_relatorio
Traceback (most recent call last):
  File "/usr/local/lib/python3.10/site-packages/sqlalchemy/engine/base.py", line 1967, in _exec_single_context
    self.dialect.do_execute(
  File "/usr/local/lib/python3.10/site-packages/sqlalchemy/engine/default.py", line 951, in do_execute
    cursor.execute(statement, parameters)
psycopg2.errors.DuplicateColumn: column "imagem_hash" of relation "fotos_relatorio" already exists
The above exception was the direct cause of the following exception:
Traceback (most recent call last):
  File "/usr/local/bin/alembic", line 7, in <module>
    sys.exit(main())
  File "/usr/local/lib/python3.10/site-packages/alembic/config.py", line 1022, in main
    CommandLine(prog=prog).main(argv=argv)
  File "/usr/local/lib/python3.10/site-packages/alembic/config.py", line 1012, in main
    self.run_cmd(cfg, options)
  File "/usr/local/lib/python3.10/site-packages/alembic/config.py", line 946, in run_cmd
    fn(
  File "/usr/local/lib/python3.10/site-packages/alembic/command.py", line 483, in upgrade
    script.run_env()
  File "/usr/local/lib/python3.10/site-packages/alembic/script/base.py", line 549, in run_env
    util.load_python_file(self.dir, "env.py")
  File "/usr/local/lib/python3.10/site-packages/alembic/util/pyfiles.py", line 116, in load_python_file
    module = load_module_py(module_id, path)
  File "/usr/local/lib/python3.10/site-packages/alembic/util/pyfiles.py", line 136, in load_module_py
    spec.loader.exec_module(module)  # type: ignore
  File "<frozen importlib._bootstrap_external>", line 883, in exec_module
  File "<frozen importlib._bootstrap>", line 241, in _call_with_frames_removed
  File "/app/migrations/env.py", line 96, in <module>
    run_migrations_online()
  File "/app/migrations/env.py", line 90, in run_migrations_online
    context.run_migrations()
  File "<string>", line 8, in run_migrations
  File "/usr/local/lib/python3.10/site-packages/alembic/runtime/environment.py", line 946, in run_migrations
    self.get_context().run_migrations(**kw)
  File "/usr/local/lib/python3.10/site-packages/alembic/runtime/migration.py", line 627, in run_migrations
    step.migration_fn(**kw)
  File "/app/migrations/versions/20251003_0100_add_image_metadata_fields.py", line 20, in upgrade
    op.add_column('fotos_relatorio', 
  File "<string>", line 8, in add_column
  File "<string>", line 3, in add_column
  File "/usr/local/lib/python3.10/site-packages/alembic/operations/ops.py", line 2186, in add_column
    return operations.invoke(op)
  File "/usr/local/lib/python3.10/site-packages/alembic/operations/base.py", line 441, in invoke
    return fn(self, operation)
  File "/usr/local/lib/python3.10/site-packages/alembic/operations/toimpl.py", line 175, in add_column
    operations.impl.add_column(
  File "/usr/local/lib/python3.10/site-packages/alembic/ddl/impl.py", line 378, in add_column
    self._exec(
  File "/usr/local/lib/python3.10/site-packages/alembic/ddl/impl.py", line 246, in _exec
    return conn.execute(construct, params)
  File "/usr/local/lib/python3.10/site-packages/sqlalchemy/engine/base.py", line 1419, in execute
    return meth(
  File "/usr/local/lib/python3.10/site-packages/sqlalchemy/sql/ddl.py", line 187, in _execute_on_connection
    return connection._execute_ddl(
  File "/usr/local/lib/python3.10/site-packages/sqlalchemy/engine/base.py", line 1530, in _execute_ddl
    ret = self._execute_context(
  File "/usr/local/lib/python3.10/site-packages/sqlalchemy/engine/base.py", line 1846, in _execute_context
    return self._exec_single_context(
  File "/usr/local/lib/python3.10/site-packages/sqlalchemy/engine/base.py", line 1986, in _exec_single_context
    self._handle_dbapi_exception(
  File "/usr/local/lib/python3.10/site-packages/sqlalchemy/engine/base.py", line 2355, in _handle_dbapi_exception
    raise sqlalchemy_exception.with_traceback(exc_info[2]) from e
  File "/usr/local/lib/python3.10/site-packages/sqlalchemy/engine/base.py", line 1967, in _exec_single_context
    self.dialect.do_execute(
  File "/usr/local/lib/python3.10/site-packages/sqlalchemy/engine/default.py", line 951, in do_execute
    cursor.execute(statement, parameters)
sqlalchemy.exc.ProgrammingError: (psycopg2.errors.DuplicateColumn) column "imagem_hash" of relation "fotos_relatorio" already exists
[SQL: ALTER TABLE fotos_relatorio ADD COLUMN imagem_hash VARCHAR(64)]
(Background on this error at: https://sqlalche.me/e/20/f405)
Stopping Container
